Workbook

Sheet Parametri
A1: PARAMETRI — modifica le celle gialle
A2: SOGLIE RARITÀ
A3: T3 — soglia rarità 3 | B3: 0.82
A4: T2 — soglia rarità 2 | B4: 0.68
A5: PESI SCORE
A6: Peso mancanti (0–1) | B6: 0.6
A7: Peso doppi inv. (0–1) | B7: 0.4
A8: FILTRI
A9: Min interazioni totali | B9: 5

Sheet Dati
A1: Annata | B1: Serie | C1: Categoria | D1: Codice | E1: Descrizione | F1: Mancanti | G1: Doppi | H1: Tot. interazioni | I1: Pct mancanti | J1: Pct doppi inv. | K1: Score | L1: Rarità calcolata | M1: Rarità attuale | N1: Stato
A2: 2025/2026 | B2: Animal Families - Crab and Monkey | C2: Compo | D2: VC025 | E2: Crab family | F2: 5 | G2: 0 | H2: 5 | I2: 0 | J2: 0 | K2: =Parametri!$B$6*I2+Parametri!$B$7*J2 | L2: =IF(K2>=Parametri!$B$3,3,IF(K2>=Parametri!$B$4,2,1)) | N2: con dati
A3: 2025/2026 | B3: Animal Families - Crab and Monkey | C3: Compo | D3: VC026 | E3: Monkey family | F3: 8 | G3: 0 | H3: 8 | I3: 1 | J3: 0 | K3: =Parametri!$B$6*I3+Parametri!$B$7*J3 | L3: =IF(K3>=Parametri!$B$3,3,IF(K3>=Parametri!$B$4,2,1)) | N3: con dati
A4: 2025/2026 | B4: Animal Families - Duck and Frog | C4: Compo | D4: VC018 | E4: Duck family | F4: 5 | G4: 0 | H4: 5 | I4: 0 | J4: 0 | K4: =Parametri!$B$6*I4+Parametri!$B$7*J4 | L4: =IF(K4>=Parametri!$B$3,3,IF(K4>=Parametri!$B$4,2,1)) | N4: con dati
A5: 2025/2026 | B5: Animal Families - Duck and Frog | C5: Compo | D5: VC019 | E5: Frog family | F5: 9 | G5: 0 | H5: 9 | I5: 1 | J5: 0 | K5: =Parametri!$B$6*I5+Parametri!$B$7*J5 | L5: =IF(K5>=Parametri!$B$3,3,IF(K5>=Parametri!$B$4,2,1)) | N5: con dati
A6: 2025/2026 | B6: Animal Families - Elephant and Giraffe | C6: Compo | D6: VC033 | E6: Elefant family | F6: 5 | G6: 0 | H6: 5 | I6: 1 | J6: 1 | K6: =Parametri!$B$6*I6+Parametri!$B$7*J6 | L6: =IF(K6>=Parametri!$B$3,3,IF(K6>=Parametri!$B$4,2,1)) | N6: con dati
A7: 2025/2026 | B7: Animal Families - Elephant and Giraffe | C7: Compo | D7: VC034 | E7: Giraffe family | F7: 5 | G7: 1 | H7: 6 | I7: 1 | J7: 0 | K7: =Parametri!$B$6*I7+Parametri!$B$7*J7 | L7: =IF(K7>=Parametri!$B$3,3,IF(K7>=Parametri!$B$4,2,1)) | N7: con dati
A8: 2025/2026 | B8: Animal Families - Hedgehog and Squirrel | C8: Compo | D8: VC020 | E8: Hedgehog family | F8: 7 | G8: 0 | H8: 7 | I8: 0 | J8: 1 | K8: =Parametri!$B$6*I8+Parametri!$B$7*J8 | L8: =IF(K8>=Parametri!$B$3,3,IF(K8>=Parametri!$B$4,2,1)) | N8: con dati
A9: 2025/2026 | B9: Animal Families - Hedgehog and Squirrel | C9: Compo | D9: VC021 | E9: Squirrel family | F9: 8 | G9: 1 | H9: 9 | I9: 1 | J9: 0 | K9: =Parametri!$B$6*I9+Parametri!$B$7*J9 | L9: =IF(K9>=Parametri!$B$3,3,IF(K9>=Parametri!$B$4,2,1)) | N9: con dati
A10: 2025/2026 | B10: Animal Families - Moose and Sheep | C10: Compo | D10: VC023 | E10: Moose family | F10: 8 | G10: 0 | H10: 8 | I10: 1 | J10: 0 | K10: =Parametri!$B$6*I10+Parametri!$B$7*J10 | L10: =IF(K10>=Parametri!$B$3,3,IF(K10>=Parametri!$B$4,2,1)) | N10: con dati
A11: 2025/2026 | B11: Animal Families - Moose and Sheep | C11: Compo | D11: VC024 | E11: Sheep family | F11: 7 | G11: 0 | H11: 7 | I11: 0 | J11: 0 | K11: =Parametri!$B$6*I11+Parametri!$B$7*J11 | L11: =IF(K11>=Parametri!$B$3,3,IF(K11>=Parametri!$B$4,2,1)) | N11: con dati
A12: 2025/2026 | B12: Animal Families - Penguin and Seal | C12: Compo | D12: VC016 | E12: Penguin family | F12: 4 | G12: 0 | H12: 4 | I12: n/d | J12: n/d | K12: n/d | L12: skippato | N12: skippato
A13: 2025/2026 | B13: Animal Families - Penguin and Seal | C13: Compo | D13: VC017 | E13: Seal family | F13: 4 | G13: 0 | H13: 4 | I13: n/d | J13: n/d | K13: n/d | L13: skippato | N13: skippato
A14: 2025/2026 | B14: Animal Families - Rabbit and Mouse | C14: Compo | D14: VC014 | E14: Rabbit family | F14: 5 | G14: 0 | H14: 5 | I14: 0 | J14: 0 | K14: =Parametri!$B$6*I14+Parametri!$B$7*J14 | L14: =IF(K14>=Parametri!$B$3,3,IF(K14>=Parametri!$B$4,2,1)) | N14: con dati
A15: 2025/2026 | B15: Animal Families - Rabbit and Mouse | C15: Compo | D15: VC015 | E15: Mouse family | F15: 6 | G15: 0 | H15: 6 | I15: 1 | J15: 0 | K15: =Parametri!$B$6*I15+Parametri!$B$7*J15 | L15: =IF(K15>=Parametri!$B$3,3,IF(K15>=Parametri!$B$4,2,1)) | N15: con dati
A16: 2025/2026 | B16: Animal Spinner | C16: Compo | D16: VC258 | E16: Sea spinner | F16: 5 | G16: 0 | H16: 5 | I16: 1 | J16: 0 | K16: =Parametri!$B$6*I16+Parametri!$B$7*J16 | L16: =IF(K16>=Parametri!$B$3,3,IF(K16>=Parametri!$B$4,2,1)) | N16: con dati
A17: 2025/2026 | B17: Animal Spinner | C17: Compo | D17: VC258A | E17: Jungle spinner | F17: 4 | G17: 0 | H17: 4 | I17: n/d | J17: n/d | K17: n/d | L17: skippato | N17: skippato
A18: 2025/2026 | B18: Animal Stamps | C18: Compo | D18: VQ047 | E18: Mouse stamp | F18: 7 | G18: 0 | H18: 7 | I18: 1 | J18: 1 | K18: =Parametri!$B$6*I18+Parametri!$B$7*J18 | L18: =IF(K18>=Parametri!$B$3,3,IF(K18>=Parametri!$B$4,2,1)) | N18: con dati
A19: 2025/2026 | B19: Animal Stamps | C19: Compo | D19: VQ048 | E19: Parrot stamp | F19: 5 | G19: 1 | H19: 6 | I19: 0 | J19: 0 | K19: =Parametri!$B$6*I19+Parametri!$B$7*J19 | L19: =IF(K19>=Parametri!$B$3,3,IF(K19>=Parametri!$B$4,2,1)) | N19: con dati
A20: 2025/2026 | B20: Christmas 2025 | C20: Hand_painted | D20: VC240 | E20: Elf green with snow scooter | F20: 8 | G20: 1 | H20: 9 | I20: 0.36363636 | J20: 0.27272727 | K20: =Parametri!$B$6*I20+Parametri!$B$7*J20 | L20: =IF(K20>=Parametri!$B$3,3,IF(K20>=Parametri!$B$4,2,1)) | N20: con dati
A21: 2025/2026 | B21: Christmas 2025 | C21: Hand_painted | D21: VD259A | E21: Santa with sleigh | F21: 7 | G21: 2 | H21: 9 | I21: 0.18181818 | J21: 0.090909091 | K21: =Parametri!$B$6*I21+Parametri!$B$7*J21 | L21: =IF(K21>=Parametri!$B$3,3,IF(K21>=Parametri!$B$4,2,1)) | N21: con dati
A22: 2025/2026 | B22: Christmas 2025 | C22: Hand_painted | D22: VD262A | E22: Reindeer on snowboard | F22: 9 | G22: 1 | H22: 10 | I22: 0.54545455 | J22: 0.27272727 | K22: =Parametri!$B$6*I22+Parametri!$B$7*J22 | L22: =IF(K22>=Parametri!$B$3,3,IF(K22>=Parametri!$B$4,2,1)) | N22: con dati
A23: 2025/2026 | B23: Christmas 2025 | C23: Hand_painted | D23: VD266B | E23: Santa with snowmobile | F23: 7 | G23: 2 | H23: 9 | I23: 0.18181818 | J23: 0.090909091 | K23: =Parametri!$B$6*I23+Parametri!$B$7*J23 | L23: =IF(K23>=Parametri!$B$3,3,IF(K23>=Parametri!$B$4,2,1)) | N23: con dati
A24: 2025/2026 | B24: Christmas 2025 | C24: Hand_painted | D24: VQ252A | E24: Gingerbread man | F24: 14 | G24: 0 | H24: 14 | I24: 1 | J24: 1 | K24: =Parametri!$B$6*I24+Parametri!$B$7*J24 | L24: =IF(K24>=Parametri!$B$3,3,IF(K24>=Parametri!$B$4,2,1)) | N24: con dati
A25: 2025/2026 | B25: Christmas 2025 | C25: Hand_painted | D25: VQ254A | E25: Santa with motor sled | F25: 10 | G25: 3 | H25: 13 | I25: 0.81818182 | J25: 0 | K25: =Parametri!$B$6*I25+Parametri!$B$7*J25 | L25: =IF(K25>=Parametri!$B$3,3,IF(K25>=Parametri!$B$4,2,1)) | N25: con dati
A26: 2025/2026 | B26: Christmas 2025 | C26: Hand_painted | D26: VQ255A | E26: Owl | F26: 8 | G26: 1 | H26: 9 | I26: 0.36363636 | J26: 0.27272727 | K26: =Parametri!$B$6*I26+Parametri!$B$7*J26 | L26: =IF(K26>=Parametri!$B$3,3,IF(K26>=Parametri!$B$4,2,1)) | N26: con dati
A27: 2025/2026 | B27: Christmas 2025 | C27: Hand_painted | D27: VQ257A | E27: Elf red with snowboard | F27: 10 | G27: 1 | H27: 11 | I27: 0.81818182 | J27: 0.27272727 | K27: =Parametri!$B$6*I27+Parametri!$B$7*J27 | L27: =IF(K27>=Parametri!$B$3,3,IF(K27>=Parametri!$B$4,2,1)) | N27: con dati
A28: 2025/2026 | B28: Christmas 2025 | C28: Hand_painted | D28: VQ259A | E28: Polar bear | F28: 9 | G28: 1 | H28: 10 | I28: 0.54545455 | J28: 0.27272727 | K28: =Parametri!$B$6*I28+Parametri!$B$7*J28 | L28: =IF(K28>=Parametri!$B$3,3,IF(K28>=Parametri!$B$4,2,1)) | N28: con dati
A29: 2025/2026 | B29: Christmas 2025 | C29: Hand_painted | D29: VQ260A | E29: Reindeer on skis | F29: 10 | G29: 1 | H29: 11 | I29: 0.81818182 | J29: 0.27272727 | K29: =Parametri!$B$6*I29+Parametri!$B$7*J29 | L29: =IF(K29>=Parametri!$B$3,3,IF(K29>=Parametri!$B$4,2,1)) | N29: con dati
... A52: 2025/2026 | B52: Demolition Stars | C52: Compo | D52: VC088 | E52: Wrecking ball | F52: 5 | G52: 1 | H52: 6 | I52: 1 | J52: 0 | K52: =Parametri!$B$6*I52+Parametri!$B$7*J52 | L52: =IF(K52>=Parametri!$B$3,3,IF(K52>=Parametri!$B$4,2,1)) | N52: con dati
A53: 2025/2026 | B53: Demolition Stars | C53: Compo | D53: VC089 | E53: Concrete nibbler | F53: 4 | G53: 0 | H53: 4 | I53: n/d | J53: n/d | K53: n/d | L53: skippato | N53: skippato
A54: 2025/2026 | B54: Do not squezze me | C54: Compo | D54: VC076 | E54: Crocodile | F54: 4 | G54: 0 | H54: 4 | I54: n/d | J54: n/d | K54: n/d | L54: skippato | N54: skippato
A55: 2025/2026 | B55: Do not squezze me | C55: Compo | D55: VC077 | E55: Parrot on the beach | F55: 4 | G55: 0 | H55: 4 | I55: n/d | J55: n/d | K55: n/d | L55: skippato | N55: skippato
A56: 2025/2026 | B56: Dodos Return | C56: Compo | D56: VC002 | E56: Dodo yellow | F56: 4 | G56: 0 | H56: 4 | I56: n/d | J56: n/d | K56: n/d | L56: skippato | N56: skippato
A57: 2025/2026 | B57: Dodos Return | C57: Compo | D57: VC002B | E57: Dodo light blue | F57: 4 | G57: 0 | H57: 4 | I57: n/d | J57: n/d | K57: n/d | L57: skippato | N57: skippato
A58: 2025/2026 | B58: Easter 2026 | C58: Hand_painted | D58: VC241 | E58: Red Bird | F58: 6 | G58: 1 | H58: 7 | I58: 0.8 | J58: 0.4 | K58: =Parametri!$B$6*I58+Parametri!$B$7*J58 | L58: =IF(K58>=Parametri!$B$3,3,IF(K58>=Parametri!$B$4,2,1)) | N58: con dati
A59: 2025/2026 | B59: Easter 2026 | C59: Hand_painted | D59: VC244 | E59: Hedgehog | F59: 6 | G59: 2 | H59: 8 | I59: 0.8 | J59: 0.1 | K59: =Parametri!$B$6*I59+Parametri!$B$7*J59 | L59: =IF(K59>=Parametri!$B$3,3,IF(K59>=Parametri!$B$4,2,1)) | N59: con dati
A60: 2025/2026 | B60: Easter 2026 | C60: Hand_painted | D60: VC245 | E60: Pink Rabbit | F60: 5 | G60: 0 | H60: 5 | I60: 0.4 | J60: 0.9 | K60: =Parametri!$B$6*I60+Parametri!$B$7*J60 | L60: =IF(K60>=Parametri!$B$3,3,IF(K60>=Parametri!$B$4,2,1)) | N60: con dati
A61: 2025/2026 | B61: Easter 2026 | C61: Hand_painted | D61: VC246 | E61: Frog | F61: 5 | G61: 1 | H61: 6 | I61: 0.4 | J61: 0.4 | K61: =Parametri!$B$6*I61+Parametri!$B$7*J61 | L61: =IF(K61>=Parametri!$B$3,3,IF(K61>=Parametri!$B$4,2,1)) | N61: con dati
A62: 2025/2026 | B62: Easter 2026 | C62: Hand_painted | D62: VC247 | E62: Black sheep | F62: 5 | G62: 1 | H62: 6 | I62: 0.4 | J62: 0.4 | K62: =Parametri!$B$6*I62+Parametri!$B$7*J62 | L62: =IF(K62>=Parametri!$B$3,3,IF(K62>=Parametri!$B$4,2,1)) | N62: con dati
...

Sheet Istruzioni
A1: COME USARE QUESTO FILE
A3: 1. Vai al foglio "Parametri" e modifica le celle GIALLE:
A4: • T3 (default 0.82): score minimo per rarità 3 — abbassa per più pezzi a 3
A5: • T2 (default 0.68): score minimo per rarità 2 — abbassa per più pezzi a 2
A6: • Peso mancanti (default 0.60): importanza dei mancanti nello score
A7: • Peso doppi inv. (default 0.40): importanza dei doppi nello score
A9: 2. Il foglio "Dati" si aggiorna automaticamente con le nuove rarità calcolate.
A11: 3. Colonne chiave:
A12: • Pct mancanti: percentile del pezzo nella serie per mancanti (0=meno, 1=più)
A13: • Pct doppi inv.: 1 - percentile per doppi (0=molti doppi, 1=pochi doppi)
A14: • Score: combinazione pesata dei due percentili
A15: • Rarità calcolata: risultato basato sulle soglie T3/T2
... A20: 5. Le righe grigie sono pezzi skippati per dati insufficienti.
